<sdf version='1.5'>
  <model name='iCub'>
    <link name='root_link'>
      <pose>0 0 0 0 -0 0</pose>
      <inertial>
        <pose>0 0 0 0 -0 0</pose>
        <mass>4.72</mass>
        <inertia>
          <ixx>0.01</ixx>
          <ixy>-3.30872e-24</ixy>
          <ixz>0</ixz>
          <iyy>0.01</iyy>
          <iyz>0</iyz>
          <izz>0.01</izz>
        </inertia>
      </inertial>
      <collision name='collision_root_link'>
        <pose>0 0 0 0 -0 3.14159</pose>
        <geometry>
          <mesh>
            <scale>1 1 1</scale>
            <uri>model://meshes/collision/icub_simple_collision_root_link.dae</uri>
          </mesh>
        </geometry>
      </collision>
      <visual name='visual_root_link'>
        <pose>0 0 0 0 -0 3.14159</pose>
        <geometry>
          <mesh>
            <scale>1 1 1</scale>
            <uri>model://meshes/visual/icub_root_link.dae</uri>
          </mesh>
        </geometry>
      </visual>
      <velocity_decay>
        <linear>0</linear>
        <angular>0</angular>
      </velocity_decay>
    </link>
    <link name='l_hip_1'>
      <pose>1.80709e-07 0.0681 -0.1199 2.65359e-06 1.57079 -2.65359e-06</pose>
      <inertial>
        <pose>0 -0.0782 0 0 -0 0</pose>
        <mass>0.754</mass>
        <inertia>
          <ixx>0.001</ixx>
          <ixy>2.059e-06</ixy>
          <ixz>1.451e-06</ixz>
          <iyy>0.001</iyy>
          <iyz>1.545e-06</iyz>
          <izz>0.001</izz>
        </inertia>
      </inertial>
      <collision name='l_hip_1_collision'>
        <pose>0 0 0 -0.785403 1.57079 -2.35619</pose>
        <geometry>
          <mesh>
            <scale>1 1 1</scale>
            <uri>model://meshes/collision/icub_simple_collision_l_hip_1.dae</uri>
          </mesh>
        </geometry>
      </collision>
      <visual name='l_hip_1_visual'>
        <pose>0 0 0 -0.785403 1.57079 -2.35619</pose>
        <geometry>
          <mesh>
            <scale>1 1 1</scale>
            <uri>model://meshes/visual/icub_l_hip_1.dae</uri>
          </mesh>
        </geometry>
      </visual>
      <velocity_decay>
        <linear>0</linear>
        <angular>0</angular>
      </velocity_decay>
    </link>
    <joint name='l_hip_pitch' type='revolute'>
      <child>l_hip_1</child>
      <parent>root_link</parent>
      <axis>
        <xyz>-5.30718e-06 -1 -9.74718e-12</xyz>
        <limit>
          <lower>-0.767945</lower>
          <upper>2.30383</upper>
          <effort>84</effort>
          <velocity>100</velocity>
        </limit>
        <dynamics>
          <damping>0.1</damping>
          <spring_reference>0</spring_reference>
          <spring_stiffness>0</spring_stiffness>
        </dynamics>
        <use_parent_model_frame>1</use_parent_model_frame>
      </axis>
    </joint>
    <link name='l_hip_2'>
      <pose>1.80709e-07 0.0681 -0.1199 3.14159 -7.34641e-06 -5.30718e-06</pose>
      <inertial>
        <pose>0 0 0.0255858 0 -0 0</pose>
        <mass>0.626</mass>
        <inertia>
          <ixx>0.00200779</ixx>
          <ixy>-7.4e-08</ixy>
          <ixz>1.0835e-05</ixz>
          <iyy>0.00200779</iyy>
          <iyz>-6.2e-08</iyz>
          <izz>0.002</izz>
        </inertia>
      </inertial>
      <collision name='l_hip_2_collision'>
        <pose>0 0 0 0.785363 -1.57079 2.35623</pose>
        <geometry>
          <mesh>
            <scale>1 1 1</scale>
            <uri>model://meshes/collision/icub_simple_collision_l_hip_2.dae</uri>
          </mesh>
        </geometry>
      </collision>
      <visual name='l_hip_2_visual'>
        <pose>0 0 0 0.785363 -1.57079 2.35623</pose>
        <geometry>
          <mesh>
            <scale>1 1 1</scale>
            <uri>model://meshes/visual/icub_l_hip_2.dae</uri>
          </mesh>
        </geometry>
      </visual>
      <velocity_decay>
        <linear>0</linear>
        <angular>0</angular>
      </velocity_decay>
    </link>
    <joint name='l_hip_roll' type='revolute'>
      <child>l_hip_2</child>
      <parent>l_hip_1</parent>
      <axis>
        <xyz>1 -5.30718e-06 7.34641e-06</xyz>
        <limit>
          <lower>-2.07694</lower>
          <upper>0.296706</upper>
          <effort>84</effort>
          <velocity>100</velocity>
        </limit>
        <dynamics>
          <damping>0.1</damping>
          <spring_reference>0</spring_reference>
          <spring_stiffness>0</spring_stiffness>
        </dynamics>
        <use_parent_model_frame>1</use_parent_model_frame>
      </axis>
    </joint>
    <link name='l_thigh'>
      <pose>1.80709e-07 0.0681 -0.1199 1.5708 -1e-05 -5.30717e-06</pose>
      <inertial>
        <pose>0.00144 -0.15943 -0.00039 0 -0 0</pose>
        <mass>2.175</mass>
        <inertia>
          <ixx>0.008</ixx>
          <ixy>-6.726e-05</ixy>
          <ixz>2.267e-06</ixz>
          <iyy>0.008</iyy>
          <iyz>3.63726e-05</iyz>
          <izz>0.008</izz>
        </inertia>
      </inertial>
      <collision name='l_thigh_collision'>
        <pose>0 0 0 -2.67795 1.57079 -1.10714</pose>
        <geometry>
          <mesh>
            <scale>1 1 1</scale>
            <uri>model://meshes/collision/icub_simple_collision_l_thigh.dae</uri>
          </mesh>
        </geometry>
      </collision>
      <visual name='l_thigh_visual'>
        <pose>0 0 0 -2.67795 1.57079 -1.10714</pose>
        <geometry>
          <mesh>
            <scale>1 1 1</scale>
            <uri>model://meshes/visual/icub_l_thigh.dae</uri>
          </mesh>
        </geometry>
      </visual>
      <velocity_decay>
        <linear>0</linear>
        <angular>0</angular>
      </velocity_decay>
    </link>
    <joint name='l_hip_yaw' type='revolute'>
      <child>l_thigh</child>
      <parent>l_hip_2</parent>
      <axis>
        <xyz>-1e-05 -1.01958e-06 1</xyz>
        <limit>
          <lower>-1.37881</lower>
          <upper>1.37881</upper>
          <effort>40</effort>
          <velocity>100</velocity>
        </limit>
        <dynamics>
          <damping>0.1</damping>
          <spring_reference>0</spring_reference>
          <spring_stiffness>0</spring_stiffness>
        </dynamics>
        <use_parent_model_frame>1</use_parent_model_frame>
      </axis>
    </joint>
    <link name='l_shank'>
      <pose>2.41671e-06 0.0681002 -0.3435 1.49636 -1.57078 -3.06716</pose>
      <inertial>
        <pose>-0.1071 0.00182 0.00211 0 -0 0</pose>
        <mass>1.264</mass>
        <inertia>
          <ixx>0.003</ixx>
          <ixy>0</ixy>
          <ixz>0</ixz>
          <iyy>0.0035</iyy>
          <iyz>0</iyz>
          <izz>0.005</izz>
        </inertia>
      </inertial>
      <collision name='l_shank_collision'>
        <pose>5.55112e-17 2.28232e-12 2.28224e-12 -3.14159 -7.26748e-17 1.5708</pose>
        <geometry>
          <mesh>
            <scale>1 1 1</scale>
            <uri>model://meshes/collision/icub_simple_collision_l_shank.dae</uri>
          </mesh>
        </geometry>
      </collision>
      <visual name='l_shank_visual'>
        <pose>5.55112e-17 2.28232e-12 2.28224e-12 -3.14159 -7.26748e-17 1.5708</pose>
        <geometry>
          <mesh>
            <scale>1 1 1</scale>
            <uri>model://meshes/visual/icub_l_shank.dae</uri>
          </mesh>
        </geometry>
      </visual>
      <velocity_decay>
        <linear>0</linear>
        <angular>0</angular>
      </velocity_decay>
    </link>
    <joint name='l_knee' type='revolute'>
      <child>l_shank</child>
      <parent>l_thigh</parent>
      <axis>
        <xyz>-7.96075e-06 -1 -1.01967e-06</xyz>
        <limit>
          <lower>-2.18166</lower>
          <upper>0.401426</upper>
          <effort>30</effort>
          <velocity>100</velocity>
        </limit>
        <dynamics>
          <damping>0.1</damping>
          <spring_reference>0</spring_reference>
          <spring_stiffness>0</spring_stiffness>
        </dynamics>
        <use_parent_model_frame>1</use_parent_model_frame>
      </axis>
    </joint>
    <link name='l_ankle_1'>
      <pose>5.3291e-06 0.0681004 -0.5565 -0.0744403 -1.57078 -3.06716</pose>
      <inertial>
        <pose>-0.0054 0.00163 0.0172 0 -0 0</pose>
        <mass>0.746</mass>
        <inertia>
          <ixx>0.001</ixx>
          <ixy>-7.081e-06</ixy>
          <ixz>4.1421e-05</ixz>
          <iyy>0.001</iyy>
          <iyz>2.0817e-05</iyz>
          <izz>0.001</izz>
        </inertia>
      </inertial>
      <collision name='l_ankle_1_collision'>
        <pose>1.11022e-16 -5.54333e-12 4.45647e-12 1.5708 1.53106e-11 1.53103e-11</pose>
        <geometry>
          <mesh>
            <scale>1 1 1</scale>
            <uri>model://meshes/collision/icub_simple_collision_l_ankle_1.dae</uri>
          </mesh>
        </geometry>
      </collision>
      <visual name='l_ankle_1_visual'>
        <pose>1.11022e-16 -5.54333e-12 4.45647e-12 1.5708 1.53106e-11 1.53103e-11</pose>
        <geometry>
          <mesh>
            <scale>1 1 1</scale>
            <uri>model://meshes/visual/icub_l_ankle_1.dae</uri>
          </mesh>
        </geometry>
      </visual>
      <velocity_decay>
        <linear>0</linear>
        <angular>0</angular>
      </velocity_decay>
    </link>
    <joint name='l_ankle_pitch' type='revolute'>
      <child>l_ankle_1</child>
      <parent>l_shank</parent>
      <axis>
        <xyz>1.1634e-05 1 1.01972e-06</xyz>
        <limit>
          <lower>-0.733038</lower>
          <upper>0.366519</upper>
          <effort>24</effort>
          <velocity>100</velocity>
        </limit>
        <dynamics>
          <damping>0.1</damping>
          <spring_reference>0</spring_reference>
          <spring_stiffness>0</spring_stiffness>
        </dynamics>
        <use_parent_model_frame>1</use_parent_model_frame>
      </axis>
    </joint>
    <link name='l_upper_foot'>
      <pose>5.3291e-06 0.0681004 -0.5565 -3.14159 -9.99999e-06 -1.1634e-05</pose>
          <inertial>
        <pose>0.0377737 0.000542627 0.022 0 -0 0</pose>
        <mass>0.861</mass>
        <inertia>
          <ixx>0.001</ixx>
          <ixy>0</ixy>
          <ixz>0</ixz>
          <iyy>0.0013</iyy>
          <iyz>0</iyz>
          <izz>0.0018</izz>
        </inertia>
      </inertial>
      <collision name='l_upper_foot_collision_l_foot'>
        <pose>-2.51615e-07 -5.54332e-12 -1.28558e-08 3.14159 1.57079 3.14159</pose>
        <geometry>
          <mesh>
            <scale>1 1 1</scale>
            <uri>model://meshes/collision/icub_simple_collision_l_foot.dae</uri>
          </mesh>
        </geometry>
      </collision>
      <visual name='l_upper_foot_visual_l_foot'>
        <pose>-2.51615e-07 -5.54332e-12 -1.28558e-08 3.14159 1.57079 3.14159</pose>
        <geometry>
          <mesh>
            <scale>1 1 1</scale>
            <uri>model://meshes/visual/icub_l_foot.dae</uri>
          </mesh>
        </geometry>
      </visual>
      <velocity_decay>
        <linear>0</linear>
        <angular>0</angular>
      </velocity_decay>
    </link>
    <joint name='l_ankle_roll' type='revolute'>
      <child>l_upper_foot</child>
      <parent>l_ankle_1</parent>
      <axis>
        <xyz>1 -1.1634e-05 9.99999e-06</xyz>
        <limit>
          <lower>-0.418879</lower>
          <upper>0.418879</upper>
          <effort>11</effort>
          <velocity>100</velocity>
        </limit>
        <dynamics>
          <damping>0.1</damping>
          <spring_reference>0</spring_reference>
          <spring_stiffness>0</spring_stiffness>
        </dynamics>
        <use_parent_model_frame>1</use_parent_model_frame>
      </axis>
    </joint>
    <link name='r_hip_1'>
      <pose>-1.80709e-07 -0.0681 -0.1199 3.14159 1.57079 -2.65359e-06</pose>
      <inertial>
        <pose>0 -0.0782 0 0 -0 0</pose>
        <mass>0.754</mass>
        <inertia>
          <ixx>0.001</ixx>
          <ixy>0</ixy>
          <ixz>0</ixz>
          <iyy>0.001</iyy>
          <iyz>0</iyz>
          <izz>0.001</izz>
        </inertia>
      </inertial>
      <collision name='r_hip_1_collision'>
        <pose>0 0 0 1.76819 -1.57079 2.76109</pose>
        <geometry>
          <mesh>
            <scale>1 1 1</scale>
            <uri>model://meshes/collision/icub_simple_collision_r_hip_1.dae</uri>
          </mesh>
        </geometry>
      </collision>
      <visual name='r_hip_1_visual'>
        <pose>0 0 0 1.76819 -1.57079 2.76109</pose>
        <geometry>
          <mesh>
            <scale>1 1 1</scale>
            <uri>model://meshes/visual/icub_r_hip_1.dae</uri>
          </mesh>
        </geometry>
      </visual>
      <velocity_decay>
        <linear>0</linear>
        <angular>0</angular>
      </velocity_decay>
    </link>
    <joint name='r_hip_pitch' type='revolute'>
      <child>r_hip_1</child>
      <parent>root_link</parent>
      <axis>
        <xyz>-2.65359e-06 -1 -1.05879e-22</xyz>
        <limit>
          <lower>-0.767945</lower>
          <upper>2.30383</upper>
          <effort>84</effort>
          <velocity>100</velocity>
        </limit>
        <dynamics>
          <damping>0.1</damping>
          <spring_reference>0</spring_reference>
          <spring_stiffness>0</spring_stiffness>
        </dynamics>
        <use_parent_model_frame>1</use_parent_model_frame>
      </axis>
    </joint>
    <link name='r_hip_2'>
      <pose>-1.80709e-07 -0.0681 -0.1199 -3.14159 -7.34641e-06 -2.65359e-06</pose>
      <inertial>
        <pose>0 0 0.0255858 0 -0 0</pose>
        <mass>0.626</mass>
        <inertia>
          <ixx>0.00200779</ixx>
          <ixy>6.61744e-24</ixy>
          <ixz>0</ixz>
          <iyy>0.00200779</iyy>
          <iyz>0</iyz>
          <izz>0.002</izz>
        </inertia>
      </inertial>
      <collision name='r_hip_2_collision'>
        <pose>0 0 0 -2.35627 -1.57079 2.35627</pose>
        <geometry>
          <mesh>
            <scale>1 1 1</scale>
            <uri>model://meshes/collision/icub_simple_collision_r_hip_2.dae</uri>
          </mesh>
        </geometry>
      </collision>
      <visual name='r_hip_2_visual'>
        <pose>0 0 0 -2.35627 -1.57079 2.35627</pose>
        <geometry>
          <mesh>
            <scale>1 1 1</scale>
            <uri>model://meshes/visual/icub_r_hip_2.dae</uri>
          </mesh>
        </geometry>
      </visual>
      <velocity_decay>
        <linear>0</linear>
        <angular>0</angular>
      </velocity_decay>
    </link>
    <joint name='r_hip_roll' type='revolute'>
      <child>r_hip_2</child>
      <parent>r_hip_1</parent>
      <axis>
        <xyz>-1 2.65359e-06 -7.34641e-06</xyz>
        <limit>
          <lower>-2.07694</lower>
          <upper>0.296706</upper>
          <effort>84</effort>
          <velocity>100</velocity>
        </limit>
        <dynamics>
          <damping>0.1</damping>
          <spring_reference>0</spring_reference>
          <spring_stiffness>0</spring_stiffness>
        </dynamics>
        <use_parent_model_frame>1</use_parent_model_frame>
      </axis>
    </joint>
    <link name='r_thigh'>
      <pose>-1.80709e-07 -0.0681 -0.1199 1.57079 -7.34641e-06 -2.65359e-06</pose>
      <inertial>
        <pose>0.00144 -0.15943 0.00039 0 -0 0</pose>
        <mass>2.175</mass>
        <inertia>
          <ixx>0.008</ixx>
          <ixy>-6.726e-05</ixy>
          <ixz>2.267e-06</ixz>
          <iyy>0.008</iyy>
          <iyz>3.63726e-05</iyz>
          <izz>0.008</izz>
        </inertia>
      </inertial>
      <collision name='r_thigh_collision'>
        <pose>0 0 0 1.57083 -1.57079 -3.26535e-05</pose>
        <geometry>
          <mesh>
            <scale>1 1 1</scale>
            <uri>model://meshes/collision/icub_simple_collision_r_thigh.dae</uri>
          </mesh>
        </geometry>
      </collision>
      <visual name='r_thigh_visual'>
        <pose>0 0 0 1.57083 -1.57079 -3.26535e-05</pose>
        <geometry>
          <mesh>
            <scale>1 1 1</scale>
            <uri>model://meshes/visual/icub_r_thigh.dae</uri>
          </mesh>
        </geometry>
      </visual>
      <velocity_decay>
        <linear>0</linear>
        <angular>0</angular>
      </velocity_decay>
    </link>
    <joint name='r_hip_yaw' type='revolute'>
      <child>r_thigh</child>
      <parent>r_hip_2</parent>
      <axis>
        <xyz>7.3464e-06 -3.67322e-06 -1</xyz>
        <limit>
          <lower>-1.37881</lower>
          <upper>1.37881</upper>
          <effort>40</effort>
          <velocity>100</velocity>
        </limit>
        <dynamics>
          <damping>0.1</damping>
          <spring_reference>0</spring_reference>
          <spring_stiffness>0</spring_stiffness>
        </dynamics>
        <use_parent_model_frame>1</use_parent_model_frame>
      </axis>
    </joint>
    <link name='r_shank'>
      <pose>1.46195e-06 -0.0681008 -0.3435 1.89254 -1.57078 2.81984</pose>
      <inertial>
        <pose>-0.1071 0.00182 -0.00211 0 -0 0</pose>
        <mass>1.264</mass>
        <inertia>
          <ixx>0.003</ixx>
          <ixy>0</ixy>
          <ixz>0</ixz>
          <iyy>0.0035</iyy>
          <iyz>0</iyz>
          <izz>0.005</izz>
        </inertia>
      </inertial>
      <collision name='r_shank_collision'>
        <pose>5.55112e-17 2.28232e-12 -2.77556e-17 3.14159 2.71835e-16 1.5708</pose>
        <geometry>
          <mesh>
            <scale>1 1 1</scale>
            <uri>model://meshes/collision/icub_simple_collision_r_shank.dae</uri>
          </mesh>
        </geometry>
      </collision>
      <visual name='r_shank_visual'>
        <pose>5.55112e-17 2.28232e-12 -2.77556e-17 3.14159 2.71835e-16 1.5708</pose>
        <geometry>
          <mesh>
            <scale>1 1 1</scale>
            <uri>model://meshes/visual/icub_r_shank.dae</uri>
          </mesh>
        </geometry>
      </visual>
      <velocity_decay>
        <linear>0</linear>
        <angular>0</angular>
      </velocity_decay>
    </link>
    <joint name='r_knee' type='revolute'>
      <child>r_shank</child>
      <parent>r_thigh</parent>
      <axis>
        <xyz>-5.30721e-06 -1 3.67318e-06</xyz>
        <limit>
          <lower>-2.18166</lower>
          <upper>0.401426</upper>
          <effort>30</effort>
          <velocity>100</velocity>
        </limit>
        <dynamics>
          <damping>0.1</damping>
          <spring_reference>0</spring_reference>
          <spring_stiffness>0</spring_stiffness>
        </dynamics>
        <use_parent_model_frame>1</use_parent_model_frame>
      </axis>
    </joint>
    <link name='r_ankle_1'>
      <pose>3.80912e-06 -0.0681016 -0.5565 -2.81984 -1.57078 2.81984</pose>
      <inertial>
        <pose>-0.0054 0.00163 -0.0172 0 -0 0</pose>
        <mass>0.746</mass>
        <inertia>
          <ixx>0.001</ixx>
          <ixy>-1.69407e-21</ixy>
          <ixz>1.35525e-20</ixz>
          <iyy>0.001</iyy>
          <iyz>3.38813e-21</iyz>
          <izz>0.001</izz>
        </inertia>
      </inertial>
      <collision name='r_ankle_1_collision'>
        <pose>1.11022e-16 -1.08707e-12 -4.45647e-12 -1.5708 -1.53106e-11 5.10353e-12</pose>
        <geometry>
          <mesh>
            <scale>1 1 1</scale>
            <uri>model://meshes/collision/icub_simple_collision_r_ankle_1.dae</uri>
          </mesh>
        </geometry>
      </collision>
      <visual name='r_ankle_1_visual'>
        <pose>1.11022e-16 -1.08707e-12 -4.45647e-12 -1.5708 -1.53106e-11 5.10353e-12</pose>
        <geometry>
          <mesh>
            <scale>1 1 1</scale>
            <uri>model://meshes/visual/icub_r_ankle_1.dae</uri>
          </mesh>
        </geometry>
      </visual>
      <velocity_decay>
        <linear>0</linear>
        <angular>0</angular>
      </velocity_decay>
    </link>
    <joint name='r_ankle_pitch' type='revolute'>
      <child>r_ankle_1</child>
      <parent>r_shank</parent>
      <axis>
        <xyz>1.634e-06 1 -3.67322e-06</xyz>
        <limit>
          <lower>-0.733038</lower>
          <upper>0.366519</upper>
          <effort>24</effort>
          <velocity>100</velocity>
        </limit>
        <dynamics>
          <damping>0.1</damping>
          <spring_reference>0</spring_reference>
          <spring_stiffness>0</spring_stiffness>
        </dynamics>
        <use_parent_model_frame>1</use_parent_model_frame>
      </axis>
    </joint>
    <link name='r_upper_foot'>
      <pose>3.80912e-06 -0.0681016 -0.5565 3.14159 -1.4236e-05 1.40032e-07</pose>
      <inertial>
        <pose>0.0377737 0.000542627 0.022 0 -0 0</pose>
        <mass>0.861</mass>
        <inertia>
          <ixx>0.001</ixx>
          <ixy>0</ixy>
          <ixz>0</ixz>
          <iyy>0.0013</iyy>
          <iyz>0</iyz>
          <izz>0.0018</izz>
        </inertia>
      </inertial>
      <collision name='r_upper_foot_collision_r_foot'>
        <pose>-2.51615e-07 1.08706e-12 -1.28558e-08 4.04298e-06 1.57079 -3.14159</pose>
        <geometry>
          <mesh>
            <scale>1 1 1</scale>
            <uri>model://meshes/collision/icub_simple_collision_r_foot.dae</uri>
          </mesh>
        </geometry>
      </collision>
      <visual name='r_upper_foot_visual_r_foot'>
        <pose>-2.51615e-07 1.08706e-12 -1.28558e-08 4.04298e-06 1.57079 -3.14159</pose>
        <geometry>
          <mesh>
            <scale>1 1 1</scale>
            <uri>model://meshes/visual/icub_r_foot.dae</uri>
          </mesh>
        </geometry>
      </visual>
      <velocity_decay>
        <linear>0</linear>
        <angular>0</angular>
      </velocity_decay>
    </link>
    <joint name='r_ankle_roll' type='revolute'>
      <child>r_upper_foot</child>
      <parent>r_ankle_1</parent>
      <axis>
        <xyz>-1 -1.40032e-07 -1.4236e-05</xyz>
        <limit>
          <lower>-0.418879</lower>
          <upper>0.418879</upper>
          <effort>11</effort>
          <velocity>100</velocity>
        </limit>
        <dynamics>
          <damping>0.1</damping>
          <spring_reference>0</spring_reference>
          <spring_stiffness>0</spring_stiffness>
        </dynamics>
        <use_parent_model_frame>1</use_parent_model_frame>
      </axis>
    </joint>
    <link name='lap_belt_1'>
      <pose>0 0 0 3.14159 -1.57079 3.14159</pose>
      <inertial>
        <pose>0 0 0 0 -0 0</pose>
        <mass>0.1</mass>
        <inertia>
          <ixx>0.0004</ixx>
          <ixy>-4.263e-05</ixy>
          <ixz>-3.889e-08</ixz>
          <iyy>0.0004</iyy>
          <iyz>0</iyz>
          <izz>0.0004</izz>
        </inertia>
      </inertial>
      <collision name='lap_belt_1_collision'>
        <pose>0 0 0 -1.5708 5.10314e-12 1.11022e-16</pose>
        <geometry>
          <mesh>
            <scale>1 1 1</scale>
            <uri>model://meshes/collision/icub_simple_collision_lap_belt_1.dae</uri>
          </mesh>
        </geometry>
      </collision>
      <visual name='lap_belt_1_visual'>
        <pose>0 0 0 -1.5708 5.10314e-12 1.11022e-16</pose>
        <geometry>
          <mesh>
            <scale>1 1 1</scale>
            <uri>model://meshes/visual/icub_lap_belt_1.dae</uri>
          </mesh>
        </geometry>
      </visual>
      <velocity_decay>
        <linear>0</linear>
        <angular>0</angular>
      </velocity_decay>
    </link>
    <joint name='torso_pitch' type='revolute'>
      <child>lap_belt_1</child>
      <parent>root_link</parent>
      <axis>
        <xyz>5.30718e-06 1 2.11758e-22</xyz>
        <limit>
          <lower>-0.383972</lower>
          <upper>1.46608</upper>
          <effort>36</effort>
          <velocity>100</velocity>
        </limit>
        <dynamics>
          <damping>0.1</damping>
          <spring_reference>0</spring_reference>
          <spring_stiffness>0</spring_stiffness>
        </dynamics>
        <use_parent_model_frame>1</use_parent_model_frame>
      </axis>
    </joint>
    <link name='lap_belt_2'>
      <pose>-1.17543e-07 6.23819e-13 0.032 -3.14159 3.67321e-06 -1.5708</pose>
      <inertial>
        <pose>0 0 0 0 -0 0</pose>
        <mass>0.1</mass>
        <inertia>
          <ixx>0.0003</ixx>
          <ixy>-1.923e-06</ixy>
          <ixz>5.095e-05</ixz>
          <iyy>0.0003</iyy>
          <iyz>-3.849e-07</iyz>
          <izz>0.0003</izz>
        </inertia>
      </inertial>
      <velocity_decay>
        <linear>0</linear>
        <angular>0</angular>
      </velocity_decay>
    </link>
    <joint name='torso_roll' type='revolute'>
      <child>lap_belt_2</child>
      <parent>lap_belt_1</parent>
      <axis>
        <xyz>-1 5.30719e-06 -7.34641e-06</xyz>
        <limit>
          <lower>-0.680678</lower>
          <upper>0.680678</upper>
          <effort>80</effort>
          <velocity>100</velocity>
        </limit>
        <dynamics>
          <damping>0.1</damping>
          <spring_reference>0</spring_reference>
          <spring_stiffness>0</spring_stiffness>
        </dynamics>
        <use_parent_model_frame>1</use_parent_model_frame>
      </axis>
    </joint>
    <link name='chest'>
      <pose>0.00549988 -2.91889e-08 0.032 1.5708 -7.34642e-06 -1.63399e-06</pose>
      <inertial>
        <pose>0.00222898 0.075 -1.18362e-17 0 -0 0</pose>
        <mass>4.81</mass>
        <inertia>
          <ixx>0.018</ixx>
          <ixy>0</ixy>
          <ixz>0</ixz>
          <iyy>0.018</iyy>
          <iyz>0</iyz>
          <izz>0.018</izz>
        </inertia>
      </inertial>
      <collision name='chest_collision'>
        <pose>-0.0055 -6.93889e-18 -3.55271e-18 -1.10717 -1.57079 2.67798</pose>
        <geometry>
          <mesh>
            <scale>1 1 1</scale>
            <uri>model://meshes/collision/icub_simple_collision_chest.dae</uri>
          </mesh>
        </geometry>
      </collision>
      <visual name='chest_visual'>
        <pose>-0.0055 -6.93889e-18 -3.55271e-18 -1.10717 -1.57079 2.67798</pose>
        <geometry>
          <mesh>
            <scale>1 1 1</scale>
            <uri>model://meshes/visual/icub_chest.dae</uri>
          </mesh>
        </geometry>
      </visual>
      <velocity_decay>
        <linear>0</linear>
        <angular>0</angular>
      </velocity_decay>
    </link>
    <joint name='torso_yaw' type='revolute'>
      <child>chest</child>
      <parent>lap_belt_2</parent>
      <axis>
        <xyz>7.34642e-06 -3.89888e-11 -1</xyz>
        <limit>
          <lower>-1.02974</lower>
          <upper>1.02974</upper>
          <effort>80</effort>
          <velocity>100</velocity>
        </limit>
        <dynamics>
          <damping>0.1</damping>
          <spring_reference>0</spring_reference>
          <spring_stiffness>0</spring_stiffness>
        </dynamics>
        <use_parent_model_frame>1</use_parent_model_frame>
      </axis>
    </joint>
    <link name='l_shoulder_1'>
      <pose>0.010749 0.11026 0.1753 -0.261794 -1.57079 3.14159</pose>
      <inertial>
        <pose>-5e-06 0.0187 -0.00119 0 -0 0</pose>
        <mass>0.189</mass>
        <inertia>
          <ixx>0.0004</ixx>
          <ixy>9e-09</ixy>
          <ixz>0</ixz>
          <iyy>0.0004</iyy>
          <iyz>-1.7e-08</iyz>
          <izz>0.0004</izz>
        </inertia>
      </inertial>
      <collision name='l_shoulder_1_collision'>
        <pose>3.08642e-14 0.109285 -0.00521101 -0.301063 1.57079 -1.87186</pose>
        <geometry>
          <mesh>
            <scale>1 1 1</scale>
            <uri>model://meshes/collision/icub_simple_collision_l_shoulder_1.dae</uri>
          </mesh>
        </geometry>
      </collision>
      <visual name='l_shoulder_1_visual'>
        <pose>3.08642e-14 0.109285 -0.00521101 -0.301063 1.57079 -1.87186</pose>
        <geometry>
          <mesh>
            <scale>1 1 1</scale>
            <uri>model://meshes/visual/icub_l_shoulder_1.dae</uri>
          </mesh>
        </geometry>
      </visual>
      <velocity_decay>
        <linear>0</linear>
        <angular>0</angular>
      </velocity_decay>
    </link>
    <joint name='l_shoulder_pitch' type='revolute'>
      <child>l_shoulder_1</child>
      <parent>chest</parent>
      <axis>
        <xyz>0.258818 0.965926 2.85203e-06</xyz>
        <limit>
          <lower>-1.65806</lower>
          <upper>0.0872665</upper>
          <effort>84</effort>
          <velocity>100</velocity>
        </limit>
        <dynamics>
          <damping>0.1</damping>
          <spring_reference>0</spring_reference>
          <spring_stiffness>0</spring_stiffness>
        </dynamics>
        <use_parent_model_frame>1</use_parent_model_frame>
      </axis>
    </joint>
    <link name='l_shoulder_2'>
      <pose>0.010749 0.11026 0.1753 3.14159 8.21174e-07 1.309</pose>
      <inertial>
        <pose>9.4e-05 -0.00627 0.0166 0 -0 0</pose>
        <mass>0.179</mass>
        <inertia>
          <ixx>0.0004</ixx>
          <ixy>4.66e-07</ixy>
          <ixz>3.65e-07</ixz>
          <iyy>0.0004</iyy>
          <iyz>-2.0524e-05</iyz>
          <izz>0.0004</izz>
        </inertia>
      </inertial>
      <collision name='l_shoulder_2_collision'>
        <pose>-0.00154529 -0.00521101 -1.11181e-12 -2.14033 1.57079 -0.569533</pose>
        <geometry>
          <mesh>
            <scale>1 1 1</scale>
            <uri>model://meshes/collision/icub_simple_collision_l_shoulder_2.dae</uri>
          </mesh>
        </geometry>
      </collision>
      <visual name='l_shoulder_2_visual'>
        <pose>-0.00154529 -0.00521101 -1.11181e-12 -2.14033 1.57079 -0.569533</pose>
        <geometry>
          <mesh>
            <scale>1 1 1</scale>
            <uri>model://meshes/visual/icub_l_shoulder_2.dae</uri>
          </mesh>
        </geometry>
      </visual>
      <velocity_decay>
        <linear>0</linear>
        <angular>0</angular>
      </velocity_decay>
    </link>
    <joint name='l_shoulder_roll' type='revolute'>
      <child>l_shoulder_2</child>
      <parent>l_shoulder_1</parent>
      <axis>
        <xyz>0.965926 -0.258818 6.97095e-06</xyz>
        <limit>
          <lower>0</lower>
          <upper>2.80649</upper>
          <effort>84</effort>
          <velocity>100</velocity>
        </limit>
        <dynamics>
          <damping>0.1</damping>
          <spring_reference>0</spring_reference>
          <spring_stiffness>0</spring_stiffness>
        </dynamics>
        <use_parent_model_frame>1</use_parent_model_frame>
      </axis>
    </joint>
    <link name='l_upper_arm'>
      <pose>0.010749 0.11026 0.1753 3.14159 -6.5209e-06 -1.634e-06</pose>
      <inertial>
        <pose>0.01321 -6.41648e-05 0.08938 0 -0 0</pose>
        <mass>0.884</mass>
        <inertia>
          <ixx>0.00102921</ixx>
          <ixy>-9.0277e-07</ixy>
          <ixz>-6.334e-05</ixz>
          <iyy>0.00103031</iyy>
          <iyz>4.03223e-06</iyz>
          <izz>0.0010011</izz>
        </inertia>
      </inertial>
      <collision name='l_upper_arm_collision_l_arm'>
        <pose>-0.0054334 0.000143363 -5.27628e-10 2.7225e-06 -3.54804e-06 -1.309</pose>
        <geometry>
          <mesh>
            <scale>1 1 1</scale>
            <uri>model://meshes/collision/icub_simple_collision_l_arm.dae</uri>
          </mesh>
        </geometry>
      </collision>
      <visual name='l_upper_arm_visual_l_arm'>
        <pose>-0.0054334 0.000143363 -5.27628e-10 2.7225e-06 -3.54804e-06 -1.309</pose>
        <geometry>
          <mesh>
            <scale>1 1 1</scale>
            <uri>model://meshes/visual/icub_l_arm.dae</uri>
          </mesh>
        </geometry>
      </visual>
      <velocity_decay>
        <linear>0</linear>
        <angular>0</angular>
      </velocity_decay>
    </link>
    <joint name='l_shoulder_yaw' type='revolute'>
      <child>l_upper_arm</child>
      <parent>l_shoulder_2</parent>
      <axis>
        <xyz>6.52089e-06 -2.5974e-06 -1</xyz>
        <limit>
          <lower>-0.645772</lower>
          <upper>1.74533</upper>
          <effort>34</effort>
          <velocity>100</velocity>
        </limit>
        <dynamics>
          <damping>0.1</damping>
          <spring_reference>0</spring_reference>
          <spring_stiffness>0</spring_stiffness>
        </dynamics>
        <use_parent_model_frame>1</use_parent_model_frame>
      </axis>
    </joint>
    <link name='l_elbow_1'>
      <pose>0.02575 0.11026 0.0230202 3.14159 -6.5209e-06 -1.634e-06</pose>
      <inertial>
        <pose>-0.0013 0.00371 -0.00105 0 -0 0</pose>
        <mass>0.1</mass>
        <inertia>
          <ixx>0.0002</ixx>
          <ixy>-5.15e-07</ixy>
          <ixz>-4.08e-07</ixz>
          <iyy>0.0002</iyy>
          <iyz>-3.71e-07</iyz>
          <izz>0.0002</izz>
        </inertia>
      </inertial>
      <velocity_decay>
        <linear>0</linear>
        <angular>0</angular>
      </velocity_decay>
    </link>
    <joint name='l_elbow' type='revolute'>
      <child>l_elbow_1</child>
      <parent>l_upper_arm</parent>
      <axis>
        <xyz>-1.63402e-06 -1 2.59739e-06</xyz>
        <limit>
          <lower>0.0959931</lower>
          <upper>1.85005</upper>
          <effort>20</effort>
          <velocity>100</velocity>
        </limit>
        <dynamics>
          <damping>0.1</damping>
          <spring_reference>0</spring_reference>
          <spring_stiffness>0</spring_stiffness>
        </dynamics>
        <use_parent_model_frame>1</use_parent_model_frame>
      </axis>
    </joint>
    <link name='l_forearm'>
      <pose>0.01075 0.11026 0.0230201 -1.5708 2.59741e-06 1.5708</pose>
      <inertial>
        <pose>0.000347 0.066 0.00476 0 -0 0</pose>
        <mass>0.525</mass>
        <inertia>
          <ixx>0.0002</ixx>
          <ixy>4.337e-06</ixy>
          <ixz>2.39e-07</ixz>
          <iyy>0.0002</iyy>
          <iyz>1.9381e-05</iyz>
          <izz>0.0002</izz>
        </inertia>
      </inertial>
      <collision name='l_forearm_collision'>
        <pose>-0.000143922 -1.25974e-12 0.0204334 -2.66395 1.57079 -1.09315</pose>
        <geometry>
          <mesh>
            <scale>1 1 1</scale>
            <uri>model://meshes/collision/icub_simple_collision_l_forearm.dae</uri>
          </mesh>
        </geometry>
      </collision>
      <visual name='l_forearm_visual'>
        <pose>-0.000143922 -1.25974e-12 0.0204334 -2.66395 1.57079 -1.09315</pose>
        <geometry>
          <mesh>
            <scale>1 1 1</scale>
            <uri>model://meshes/visual/icub_l_forearm.dae</uri>
          </mesh>
        </geometry>
      </visual>
      <velocity_decay>
        <linear>0</linear>
        <angular>0</angular>
      </velocity_decay>
    </link>
    <joint name='l_wrist_prosup' type='revolute'>
      <child>l_forearm</child>
      <parent>l_elbow_1</parent>
      <axis>
        <xyz>2.84769e-06 -2.59741e-06 -1</xyz>
        <limit>
          <lower>-0.872665</lower>
          <upper>0.872665</upper>
          <effort>0.45</effort>
          <velocity>100</velocity>
        </limit>
        <dynamics>
          <damping>0.1</damping>
          <spring_reference>0</spring_reference>
          <spring_stiffness>0</spring_stiffness>
        </dynamics>
        <use_parent_model_frame>1</use_parent_model_frame>
      </axis>
    </joint>
    <link name='l_wrist_1'>
      <pose>0.0107504 0.110259 -0.11428 -2.7153 1.57079 -1.14451</pose>
      <inertial>
        <pose>0 0 0 0 -0 0</pose>
        <mass>0.1</mass>
        <inertia>
          <ixx>0.0002</ixx>
          <ixy>0</ixy>
          <ixz>0</ixz>
          <iyy>0.0002</iyy>
          <iyz>0</iyz>
          <izz>0.0002</izz>
        </inertia>
      </inertial>
      <velocity_decay>
        <linear>0</linear>
        <angular>0</angular>
      </velocity_decay>
    </link>
    <joint name='l_wrist_pitch' type='revolute'>
      <child>l_wrist_1</child>
      <parent>l_forearm</parent>
      <axis>
        <xyz>-1 1.63401e-06 -2.84771e-06</xyz>
        <limit>
          <lower>-1.13446</lower>
          <upper>0.174533</upper>
          <effort>0.65</effort>
          <velocity>100</velocity>
        </limit>
        <dynamics>
          <damping>0.1</damping>
          <spring_reference>0</spring_reference>
          <spring_stiffness>0</spring_stiffness>
        </dynamics>
        <use_parent_model_frame>1</use_parent_model_frame>
      </axis>
    </joint>
    <link name='l_hand'>
      <pose>0.0107504 0.110259 -0.11428 -2.7153 1.57079 -1.14451</pose>
      <inertial>
        <pose>0.07023 -0.00805 -0.007 0 -0 0</pose>
        <mass>0.213</mass>
        <inertia>
          <ixx>0.0001</ixx>
          <ixy>1.278e-05</ixy>
          <ixz>4.823e-06</ixz>
          <iyy>0.0001</iyy>
          <iyz>-1.8188e-05</iyz>
          <izz>0.0001</izz>
        </inertia>
      </inertial>
      <collision name='l_hand_collision'>
        <pose>-1.25974e-12 0.0204334 -0.000143922 5.10271e-12 -2.6418e-12 1.49622e-11</pose>
        <geometry>
          <mesh>
            <scale>1 1 1</scale>
            <uri>model://meshes/collision/icub_simple_collision_l_hand.dae</uri>
          </mesh>
        </geometry>
      </collision>
      <visual name='l_hand_visual'>
        <pose>-1.25974e-12 0.0204334 -0.000143922 5.10271e-12 -2.6418e-12 1.49622e-11</pose>
        <geometry>
          <mesh>
            <scale>1 1 1</scale>
            <uri>model://meshes/visual/icub_l_hand.dae</uri>
          </mesh>
        </geometry>
      </visual>
      <velocity_decay>
        <linear>0</linear>
        <angular>0</angular>
      </velocity_decay>
    </link>
    <joint name='l_wrist_yaw' type='revolute'>
      <child>l_hand</child>
      <parent>l_wrist_1</parent>
      <axis>
        <xyz>1.63403e-06 1 -6.27061e-06</xyz>
        <limit>
          <lower>-0.436332</lower>
          <upper>0.436332</upper>
          <effort>0.65</effort>
          <velocity>100</velocity>
        </limit>
        <dynamics>
          <damping>0.1</damping>
          <spring_reference>0</spring_reference>
          <spring_stiffness>0</spring_stiffness>
        </dynamics>
        <use_parent_model_frame>1</use_parent_model_frame>
      </axis>
    </joint>
    <link name='neck_1'>
      <pose>0.00780846 -3.29559e-08 0.2253 6.12201e-06 -1.57079 3.14159</pose>
      <inertial>
        <pose>0 0 0 0 -0 0</pose>
        <mass>0.1</mass>
        <inertia>
          <ixx>0.0002</ixx>
          <ixy>0</ixy>
          <ixz>0</ixz>
          <iyy>0.0002</iyy>
          <iyz>0</iyz>
          <izz>0.0002</izz>
        </inertia>
      </inertial>
      <collision name='neck_1_collision'>
        <pose>-5.55112e-17 9.62889e-13 -0.0055 3.14159 -1.57079 1.5708</pose>
        <geometry>
          <mesh>
            <scale>1 1 1</scale>
            <uri>model://meshes/collision/icub_simple_collision_neck_1.dae</uri>
          </mesh>
        </geometry>
      </collision>
      <visual name='neck_1_visual'>
        <pose>-5.55112e-17 9.62889e-13 -0.0055 3.14159 -1.57079 1.5708</pose>
        <geometry>
          <mesh>
            <scale>1 1 1</scale>
            <uri>model://meshes/visual/icub_neck_1.dae</uri>
          </mesh>
        </geometry>
      </visual>
      <velocity_decay>
        <linear>0</linear>
        <angular>0</angular>
      </velocity_decay>
    </link>
    <joint name='neck_pitch' type='revolute'>
      <child>neck_1</child>
      <parent>chest</parent>
      <axis>
        <xyz>2.03922e-06 -1 6.74623e-11</xyz>
        <limit>
          <lower>-0.698132</lower>
          <upper>0.523599</upper>
          <effort>20</effort>
          <velocity>100</velocity>
        </limit>
        <dynamics>
          <damping>0.1</damping>
          <spring_reference>0</spring_reference>
          <spring_stiffness>0</spring_stiffness>
        </dynamics>
        <use_parent_model_frame>1</use_parent_model_frame>
      </axis>
    </joint>
    <link name='neck_2'>
      <pose>0.00780836 -3.29555e-08 0.2348 -1.46928e-05 3.67327e-06 1.5708</pose>
      <inertial>
        <pose>0 0 0 0 -0 0</pose>
        <mass>0.1</mass>
        <inertia>
          <ixx>0.0002</ixx>
          <ixy>0</ixy>
          <ixz>0</ixz>
          <iyy>0.0002</iyy>
          <iyz>0</iyz>
          <izz>0.0002</izz>
        </inertia>
      </inertial>
      <collision name='neck_2_collision'>
        <pose>-9.62885e-13 0.0055 0.0235 -3.14157 -1.57079 -1.57082</pose>
        <geometry>
          <mesh>
            <scale>1 1 1</scale>
            <uri>model://meshes/collision/icub_simple_collision_neck_2.dae</uri>
          </mesh>
        </geometry>
      </collision>
      <visual name='neck_2_visual'>
        <pose>-9.62885e-13 0.0055 0.0235 -3.14157 -1.57079 -1.57082</pose>
        <geometry>
          <mesh>
            <scale>1 1 1</scale>
            <uri>model://meshes/visual/icub_neck_2.dae</uri>
          </mesh>
        </geometry>
      </visual>
      <velocity_decay>
        <linear>0</linear>
        <angular>0</angular>
      </velocity_decay>
    </link>
    <joint name='neck_roll' type='revolute'>
      <child>neck_2</child>
      <parent>neck_1</parent>
      <axis>
        <xyz>1 2.03923e-06 1.46928e-05</xyz>
        <limit>
          <lower>-1.22173</lower>
          <upper>1.0472</upper>
          <effort>20</effort>
          <velocity>100</velocity>
        </limit>
        <dynamics>
          <damping>0.1</damping>
          <spring_reference>0</spring_reference>
          <spring_stiffness>0</spring_stiffness>
        </dynamics>
        <use_parent_model_frame>1</use_parent_model_frame>
      </axis>
    </joint>
    <link name='head'>
      <pose>0.00780836 -3.29555e-08 0.2348 -1.5708 1.46928e-05 -3.14159</pose>
      <inertial>
        <pose>0.0185 -0.1108 6.78454e-18 0 -0 0</pose>
        <mass>1.33687</mass>
        <inertia>
          <ixx>0.006</ixx>
          <ixy>0</ixy>
          <ixz>0</ixz>
          <iyy>0.006</iyy>
          <iyz>0</iyz>
          <izz>0.006</izz>
        </inertia>
      </inertial>
      <collision name='head_collision'>
        <pose>0.0045 -0.0235 9.42472e-13 -1.32582 1.57079 -2.89662</pose>
        <geometry>
          <mesh>
            <scale>1 1 1</scale>
            <uri>model://meshes/collision/icub_simple_collision_head.dae</uri>
          </mesh>
        </geometry>
      </collision>
      <visual name='head_visual'>
        <pose>0.0045 -0.0235 9.42472e-13 -1.32582 1.57079 -2.89662</pose>
        <geometry>
          <mesh>
            <scale>1 1 1</scale>
            <uri>model://meshes/visual/icub_head.dae</uri>
          </mesh>
        </geometry>
      </visual>
      <velocity_decay>
        <linear>0</linear>
        <angular>0</angular>
      </velocity_decay>
       <sensor name="imu_sensor" type="imu">
        <always_on>1</always_on>
        <update_rate>100</update_rate>
        <visualize>1</visualize>
        <imu/>
        <plugin filename="libgazebo_yarp_imu.so" name="iCub_yarp_gazebo_plugin_IMU">
            <yarpConfigurationFile>model://conf/gazebo_icub_inertial.ini</yarpConfigurationFile>
        </plugin>
        <pose>0.0185 -0.1108 0.0066 1.5708 -0 0</pose>
      </sensor>
    </link>
    <joint name='neck_yaw' type='revolute'>
      <child>head</child>
      <parent>neck_2</parent>
      <axis>
        <xyz>-1.46928e-05 3.75006e-11 1</xyz>
        <limit>
          <lower>-0.959931</lower>
          <upper>0.959931</upper>
          <effort>20</effort>
          <velocity>100</velocity>
        </limit>
        <dynamics>
          <damping>0.1</damping>
          <spring_reference>0</spring_reference>
          <spring_stiffness>0</spring_stiffness>
        </dynamics>
        <use_parent_model_frame>1</use_parent_model_frame>
      </axis>
    </joint>
    <link name='r_shoulder_1'>
      <pose>0.0107486 -0.11026 0.1753 -2.87979 -1.57079 3.14159</pose>
      <inertial>
        <pose>5e-06 0.0187 0.00119 0 -0 0</pose>
        <mass>0.189</mass>
        <inertia>
          <ixx>0.0004</ixx>
          <ixy>2.1e-08</ixy>
          <ixz>-1e-09</ixz>
          <iyy>0.0004</iyy>
          <iyz>4.22e-06</iyz>
          <izz>0.0004</izz>
        </inertia>
      </inertial>
      <collision name='r_shoulder_1_collision'>
        <pose>-3.08642e-14 0.109285 0.00521101 3.06003 1.57079 -1.65235</pose>
        <geometry>
          <mesh>
            <scale>1 1 1</scale>
            <uri>model://meshes/collision/icub_simple_collision_r_shoulder_1.dae</uri>
          </mesh>
        </geometry>
      </collision>
      <visual name='r_shoulder_1_visual'>
        <pose>-3.08642e-14 0.109285 0.00521101 3.06003 1.57079 -1.65235</pose>
        <geometry>
          <mesh>
            <scale>1 1 1</scale>
            <uri>model://meshes/visual/icub_r_shoulder_1.dae</uri>
          </mesh>
        </geometry>
      </visual>
      <velocity_decay>
        <linear>0</linear>
        <angular>0</angular>
      </velocity_decay>
    </link>
    <joint name='r_shoulder_pitch' type='revolute'>
      <child>r_shoulder_1</child>
      <parent>chest</parent>
      <axis>
        <xyz>-0.258815 0.965927 -2.85208e-06</xyz>
        <limit>
          <lower>-1.65806</lower>
          <upper>0.0872665</upper>
          <effort>84</effort>
          <velocity>100</velocity>
        </limit>
        <dynamics>
          <damping>0.1</damping>
          <spring_reference>0</spring_reference>
          <spring_stiffness>0</spring_stiffness>
        </dynamics>
        <use_parent_model_frame>1</use_parent_model_frame>
      </axis>
    </joint>
    <link name='r_shoulder_2'>
      <pose>0.0107486 -0.11026 0.1753 6.97094e-06 8.21122e-07 -1.309</pose>
      <inertial>
        <pose>-9.4e-05 -0.00627 -0.0166 0 -0 0</pose>
        <mass>0.179</mass>
        <inertia>
          <ixx>0.0004</ixx>
          <ixy>-4.53e-07</ixy>
          <ixz>2.03e-07</ixz>
          <iyy>0.0004</iyy>
          <iyz>2.07e-05</iyz>
          <izz>0.0004</izz>
        </inertia>
      </inertial>
      <collision name='r_shoulder_2_collision'>
        <pose>-0.00154529 -0.00521101 -1.11181e-12 -1.00125 -1.57079 2.57205</pose>
        <geometry>
          <mesh>
            <scale>1 1 1</scale>
            <uri>model://meshes/collision/icub_simple_collision_r_shoulder_2.dae</uri>
          </mesh>
        </geometry>
      </collision>
      <visual name='r_shoulder_2_visual'>
        <pose>-0.00154529 -0.00521101 -1.11181e-12 -1.00125 -1.57079 2.57205</pose>
        <geometry>
          <mesh>
            <scale>1 1 1</scale>
            <uri>model://meshes/visual/icub_r_shoulder_2.dae</uri>
          </mesh>
        </geometry>
      </visual>
      <velocity_decay>
        <linear>0</linear>
        <angular>0</angular>
      </velocity_decay>
    </link>
    <joint name='r_shoulder_roll' type='revolute'>
      <child>r_shoulder_2</child>
      <parent>r_shoulder_1</parent>
      <axis>
        <xyz>-0.965927 -0.258815 -6.97094e-06</xyz>
        <limit>
          <lower>0</lower>
          <upper>2.80649</upper>
          <effort>84</effort>
          <velocity>100</velocity>
        </limit>
        <dynamics>
          <damping>0.1</damping>
          <spring_reference>0</spring_reference>
          <spring_stiffness>0</spring_stiffness>
        </dynamics>
        <use_parent_model_frame>1</use_parent_model_frame>
      </axis>
    </joint>
    <link name='r_upper_arm'>
      <pose>0.0107486 -0.11026 0.1753 3.14159 -6.5209e-06 -1.63398e-06</pose>
      <inertial>
        <pose>0.01321 6.38356e-05 0.08938 0 -0 0</pose>
        <mass>0.884</mass>
        <inertia>
          <ixx>0.00103006</ixx>
          <ixy>-8.50772e-07</ixy>
          <ixz>-6.39001e-05</ixz>
          <iyy>0.00103116</iyy>
          <iyz>-3.60876e-06</iyz>
          <izz>0.00100111</izz>
        </inertia>
      </inertial>
      <collision name='r_upper_arm_collision_r_arm'>
        <pose>-0.0054334 -0.000144427 5.29682e-10 3.14159 2.86125e-06 1.309</pose>
        <geometry>
          <mesh>
            <scale>1 1 1</scale>
            <uri>model://meshes/collision/icub_simple_collision_r_arm.dae</uri>
          </mesh>
        </geometry>
      </collision>
      <visual name='r_upper_arm_visual_r_arm'>
        <pose>-0.0054334 -0.000144427 5.29682e-10 3.14159 2.86125e-06 1.309</pose>
        <geometry>
          <mesh>
            <scale>1 1 1</scale>
            <uri>model://meshes/visual/icub_r_arm.dae</uri>
          </mesh>
        </geometry>
      </visual>
      <velocity_decay>
        <linear>0</linear>
        <angular>0</angular>
      </velocity_decay>
    </link>
    <joint name='r_shoulder_yaw' type='revolute'>
      <child>r_upper_arm</child>
      <parent>r_shoulder_2</parent>
      <axis>
        <xyz>-6.5209e-06 5.62654e-08 1</xyz>
        <limit>
          <lower>-0.645772</lower>
          <upper>1.74533</upper>
          <effort>34</effort>
          <velocity>100</velocity>
        </limit>
        <dynamics>
          <damping>0.1</damping>
          <spring_reference>0</spring_reference>
          <spring_stiffness>0</spring_stiffness>
        </dynamics>
        <use_parent_model_frame>1</use_parent_model_frame>
      </axis>
    </joint>
    <link name='r_elbow_1'>
      <pose>0.0257496 -0.11026 0.0230202 7.40268e-06 6.5209e-06 -3.14159</pose>
      <inertial>
        <pose>0.0013 -0.00371 0.00105 0 -0 0</pose>
        <mass>0.1</mass>
        <inertia>
          <ixx>0.0002</ixx>
          <ixy>-5.02e-07</ixy>
          <ixz>-3.99e-07</ixz>
          <iyy>0.0002</iyy>
          <iyz>-3.71e-07</iyz>
          <izz>0.0002</izz>
        </inertia>
      </inertial>
      <velocity_decay>
        <linear>0</linear>
        <angular>0</angular>
      </velocity_decay>
    </link>
    <joint name='r_elbow' type='revolute'>
      <child>r_elbow_1</child>
      <parent>r_upper_arm</parent>
      <axis>
        <xyz>1.01957e-06 -1 7.40268e-06</xyz>
        <limit>
          <lower>0.0959931</lower>
          <upper>1.85005</upper>
          <effort>20</effort>
          <velocity>100</velocity>
        </limit>
        <dynamics>
          <damping>0.1</damping>
          <spring_reference>0</spring_reference>
          <spring_stiffness>0</spring_stiffness>
        </dynamics>
        <use_parent_model_frame>1</use_parent_model_frame>
      </axis>
    </joint>
    <link name='r_forearm'>
      <pose>0.0107496 -0.11026 0.0230201 1.57079 7.40266e-06 1.57079</pose>
      <inertial>
        <pose>-0.000347 -0.066 -0.00476 0 -0 0</pose>
        <mass>0.525</mass>
        <inertia>
          <ixx>0.0004</ixx>
          <ixy>5.66e-06</ixy>
          <ixz>1.4e-06</ixz>
          <iyy>0.0004</iyy>
          <iyz>1.82e-05</iyz>
          <izz>0.0004</izz>
        </inertia>
      </inertial>
      <collision name='r_forearm_collision'>
        <pose>0.000143922 -1.07213e-12 -0.0204334 -1.74166 1.57079 -0.170863</pose>
        <geometry>
          <mesh>
            <scale>1 1 1</scale>
            <uri>model://meshes/collision/icub_simple_collision_r_forearm.dae</uri>
          </mesh>
        </geometry>
      </collision>
      <visual name='r_forearm_visual'>
        <pose>0.000143922 -1.07213e-12 -0.0204334 -1.74166 1.57079 -0.170863</pose>
        <geometry>
          <mesh>
            <scale>1 1 1</scale>
            <uri>model://meshes/visual/icub_r_forearm.dae</uri>
          </mesh>
        </geometry>
      </visual>
      <velocity_decay>
        <linear>0</linear>
        <angular>0</angular>
      </velocity_decay>
    </link>
    <joint name='r_wrist_prosup' type='revolute'>
      <child>r_forearm</child>
      <parent>r_elbow_1</parent>
      <axis>
        <xyz>-2.8477e-06 7.40267e-06 1</xyz>
        <limit>
          <lower>-0.872665</lower>
          <upper>0.872665</upper>
          <effort>0.45</effort>
          <velocity>100</velocity>
        </limit>
        <dynamics>
          <damping>0.1</damping>
          <spring_reference>0</spring_reference>
          <spring_stiffness>0</spring_stiffness>
        </dynamics>
        <use_parent_model_frame>1</use_parent_model_frame>
      </axis>
    </joint>
    <link name='r_wrist_1'>
      <pose>0.01075 -0.110261 -0.11428 2.48946 -1.57079 2.22293</pose>
      <inertial>
        <pose>0 0 0 0 -0 0</pose>
        <mass>0.1</mass>
        <inertia>
          <ixx>0.0002</ixx>
          <ixy>0</ixy>
          <ixz>0</ixz>
          <iyy>0.0002</iyy>
          <iyz>0</iyz>
          <izz>0.0002</izz>
        </inertia>
      </inertial>
      <velocity_decay>
        <linear>0</linear>
        <angular>0</angular>
      </velocity_decay>
    </link>
    <joint name='r_wrist_pitch' type='revolute'>
      <child>r_wrist_1</child>
      <parent>r_forearm</parent>
      <axis>
        <xyz>1 1.01959e-06 2.84771e-06</xyz>
        <limit>
          <lower>-1.13446</lower>
          <upper>0.174533</upper>
          <effort>0.65</effort>
          <velocity>100</velocity>
        </limit>
        <dynamics>
          <damping>0.1</damping>
          <spring_reference>0</spring_reference>
          <spring_stiffness>0</spring_stiffness>
        </dynamics>
        <use_parent_model_frame>1</use_parent_model_frame>
      </axis>
    </joint>
    <link name='r_hand'>
      <pose>0.01075 -0.110261 -0.11428 -2.16655 1.57079 -0.595755</pose>
      <inertial>
        <pose>0.07023 -0.00805 0.007 0 -0 0</pose>
        <mass>0.213</mass>
        <inertia>
          <ixx>0.0002</ixx>
          <ixy>1.26e-05</ixy>
          <ixz>-6.08e-06</ixz>
          <iyy>0.0002</iyy>
          <iyz>1.76e-05</iyz>
          <izz>0.0002</izz>
        </inertia>
      </inertial>
      <collision name='r_hand_collision'>
        <pose>1.0721e-12 0.0204334 0.000143922 1.53098e-11 2.00653e-11 -3.14159</pose>
        <geometry>
          <mesh>
            <scale>1 1 1</scale>
            <uri>model://meshes/collision/icub_simple_collision_r_hand.dae</uri>
          </mesh>
        </geometry>
      </collision>
      <visual name='r_hand_visual'>
        <pose>1.0721e-12 0.0204334 0.000143922 1.53098e-11 2.00653e-11 -3.14159</pose>
        <geometry>
          <mesh>
            <scale>1 1 1</scale>
            <uri>model://meshes/visual/icub_r_hand.dae</uri>
          </mesh>
        </geometry>
      </visual>
      <velocity_decay>
        <linear>0</linear>
        <angular>0</angular>
      </velocity_decay>
    </link>
    <joint name='r_wrist_yaw' type='revolute'>
      <child>r_hand</child>
      <parent>r_wrist_1</parent>
      <axis>
        <xyz>-1.01958e-06 1 -3.72946e-06</xyz>
        <limit>
          <lower>-0.436332</lower>
          <upper>0.436332</upper>
          <effort>0.65</effort>
          <velocity>100</velocity>
        </limit>
        <dynamics>
          <damping>0.1</damping>
          <spring_reference>0</spring_reference>
          <spring_stiffness>0</spring_stiffness>
        </dynamics>
        <use_parent_model_frame>1</use_parent_model_frame>
      </axis>
    </joint>
  </model>
</sdf>
